2013-12-26 16:22:45,859 ERROR: An error occurred custom_logging [in /home/k/Programs/python/boiler_plate/custom_logging.py:22]
2013-12-26 16:22:45,859 DEBUG: A value for debugging custom_logging [in /home/k/Programs/python/boiler_plate/custom_logging.py:23]
2013-12-26 16:22:45,860 WARNING: A warning occurred (42 apples) custom_logging [in /home/k/Programs/python/boiler_plate/custom_logging.py:24]
2013-12-26 16:22:45,860 INFO: My App custom_logging [in /home/k/Programs/python/boiler_plate/custom_logging.py:25]
2013-12-26 16:22:45,997 ERROR: An error occurred custom_logging [in /home/k/Programs/python/boiler_plate/custom_logging.py:22]
2013-12-26 16:22:45,997 DEBUG: A value for debugging custom_logging [in /home/k/Programs/python/boiler_plate/custom_logging.py:23]
2013-12-26 16:22:45,997 WARNING: A warning occurred (42 apples) custom_logging [in /home/k/Programs/python/boiler_plate/custom_logging.py:24]
2013-12-26 16:22:45,997 INFO: My App custom_logging [in /home/k/Programs/python/boiler_plate/custom_logging.py:25]
2013-12-26 16:22:51,699 ERROR: Internal Error __init__ [in /usr/local/lib/python2.7/dist-packages/flask_restful/__init__.py:167]
Traceback (most recent call last):
  File "/usr/local/lib/python2.7/dist-packages/flask/app.py", line 1475, in full_dispatch_request
    rv = self.dispatch_request()
  File "/usr/local/lib/python2.7/dist-packages/flask/app.py", line 1461, in dispatch_request
    return self.view_functions[rule.endpoint](**req.view_args)
  File "/usr/local/lib/python2.7/dist-packages/flask_restful/__init__.py", line 252, in wrapper
    resp = resource(*args, **kwargs)
  File "/usr/local/lib/python2.7/dist-packages/flask/views.py", line 84, in view
    return self.dispatch_request(*args, **kwargs)
  File "/usr/local/lib/python2.7/dist-packages/flask_restful/__init__.py", line 332, in dispatch_request
    resp = meth(*args, **kwargs)
  File "./api.py", line 87, in get
    instance = Instagram(CLIENT_ID, CLIENT_SECRET)
TypeError: object.__new__() takes no parameters
2013-12-26 16:22:53,190 ERROR: Internal Error __init__ [in /usr/local/lib/python2.7/dist-packages/flask_restful/__init__.py:167]
Traceback (most recent call last):
  File "/usr/local/lib/python2.7/dist-packages/flask/app.py", line 1475, in full_dispatch_request
    rv = self.dispatch_request()
  File "/usr/local/lib/python2.7/dist-packages/flask/app.py", line 1461, in dispatch_request
    return self.view_functions[rule.endpoint](**req.view_args)
  File "/usr/local/lib/python2.7/dist-packages/flask_restful/__init__.py", line 252, in wrapper
    resp = resource(*args, **kwargs)
  File "/usr/local/lib/python2.7/dist-packages/flask/views.py", line 84, in view
    return self.dispatch_request(*args, **kwargs)
  File "/usr/local/lib/python2.7/dist-packages/flask_restful/__init__.py", line 332, in dispatch_request
    resp = meth(*args, **kwargs)
  File "./api.py", line 87, in get
    instance = Instagram(CLIENT_ID, CLIENT_SECRET)
TypeError: object.__new__() takes no parameters
2013-12-26 16:22:53,644 ERROR: Internal Error __init__ [in /usr/local/lib/python2.7/dist-packages/flask_restful/__init__.py:167]
Traceback (most recent call last):
  File "/usr/local/lib/python2.7/dist-packages/flask/app.py", line 1475, in full_dispatch_request
    rv = self.dispatch_request()
  File "/usr/local/lib/python2.7/dist-packages/flask/app.py", line 1461, in dispatch_request
    return self.view_functions[rule.endpoint](**req.view_args)
  File "/usr/local/lib/python2.7/dist-packages/flask_restful/__init__.py", line 252, in wrapper
    resp = resource(*args, **kwargs)
  File "/usr/local/lib/python2.7/dist-packages/flask/views.py", line 84, in view
    return self.dispatch_request(*args, **kwargs)
  File "/usr/local/lib/python2.7/dist-packages/flask_restful/__init__.py", line 332, in dispatch_request
    resp = meth(*args, **kwargs)
  File "./api.py", line 87, in get
    instance = Instagram(CLIENT_ID, CLIENT_SECRET)
TypeError: object.__new__() takes no parameters
2013-12-26 16:22:53,986 ERROR: Internal Error __init__ [in /usr/local/lib/python2.7/dist-packages/flask_restful/__init__.py:167]
Traceback (most recent call last):
  File "/usr/local/lib/python2.7/dist-packages/flask/app.py", line 1475, in full_dispatch_request
    rv = self.dispatch_request()
  File "/usr/local/lib/python2.7/dist-packages/flask/app.py", line 1461, in dispatch_request
    return self.view_functions[rule.endpoint](**req.view_args)
  File "/usr/local/lib/python2.7/dist-packages/flask_restful/__init__.py", line 252, in wrapper
    resp = resource(*args, **kwargs)
  File "/usr/local/lib/python2.7/dist-packages/flask/views.py", line 84, in view
    return self.dispatch_request(*args, **kwargs)
  File "/usr/local/lib/python2.7/dist-packages/flask_restful/__init__.py", line 332, in dispatch_request
    resp = meth(*args, **kwargs)
  File "./api.py", line 87, in get
    instance = Instagram(CLIENT_ID, CLIENT_SECRET)
TypeError: object.__new__() takes no parameters
